Workbook

Sheet Resumo
A1: Confissão de Dívida - Cemil Tubos e Conexões
A2: Ao valor confessado, serão incorporados mensalmente correção monetária com base na Taxa SELIC (aplicados sobre o valor da dívida ativa)
A3: Saldo inicial (original) | B3: 2983673
A4: Abatimento Tecnomonte (amortização) | B4: -172364.3
A5: Valor parcela | B5: =Parâmetros!B5 -> 20000
A6: Total pago (Parcelas semanais de R$20.000,00 pagas até 19/09/2025) | B6: =-32*Parâmetros!B5 -> -640000
A7: Saldo Atual | B7: =SUM(B3+B4+B6) -> 2171308.7
A8: Observação: | B8: O nº de parcelas extras depende da SELIC lançada mês a mês.

Sheet Parâmetros
A1: Parâmetros do Acordo
A3: Saldo inicial (data base) | B3: 2171308.7
A4: Data base (início) | B4: 45926
A5: Valor parcela (fixa) | B5: 20000
A7: Tabela SELIC (mensal)
A8: Competência (AAAA-MM) | B8: Taxa Mensal (%)
A9: 2025-08 | B9: 0.0116
A10: 2025-09 | B10: 0.0122
A11: 2025-10 | B11: 0.0128
A12: 2025-11 | B12: 0.0105
A13: 2025-12 | B13: 0.0122
A14: 2026-01 | B14: 0.0116
A15: 2026-02 | B15: 0.0116
A16: 2026-03 | B16: 0
A17: 2026-04 | B17: 0
A18: 2026-05 | B18: 0
A19: 2026-06 | B19: 0
A20: 2026-07 | B20: 0
... A25: 2026-12 | B25: 0

Sheet Modelo B
A1: Resumo do Acordo – Confissão de Dívida
A2: Valor da dívida (base) | B2: =Parâmetros!B3 -> 2171308.7 | E2: Valor da parcela | F2: =Parâmetros!B5 -> 20000
A3: *Se cair em feriado, antecipar manualmente a data para o dia útil anterior.
A5: Parcela # | B5: Data prevista | C5: Dia da semana | D5: Valor parcela | E5: Data pagamento | F5: Valor pago | G5: Saldo anterior | H5: Juros (Selic mês) | I5: Amortização | J5: Saldo após pagamento | K5: Observações
A6: 28 | B6: 45891 | C6: Friday | D6: =Parâmetros!B5 -> 20000 | E6: 45891 | F6: =D6 -> 20000 | G6: =$B$2 -> 2171308.7 | I6: =MIN(D6,G6) -> 20000 | J6: =G6-I6+H6 -> 2151308.7
A7: 29 | B7: 45898 | C7: Friday | D7: =Parâmetros!B5 -> 20000 | E7: 45898 | F7: =D7 -> 20000 | G7: =J6 -> 2151308.7 | I7: =MIN(D7,G7) -> 20000 | J7: =G7-I7+H7 -> 2131308.7
A8: 30 | B8: 45905 | C8: Friday | D8: =Parâmetros!B5 -> 20000 | E8: 45905 | F8: =D8 -> 20000 | G8: =J7 -> 2131308.7 | I8: =MIN(D8,G8) -> 20000 | J8: =G8-I8+H8 -> 2111308.7
A9: 31 | B9: 45912 | C9: Friday | D9: =Parâmetros!B5 -> 20000 | E9: 45912 | F9: =D9 -> 20000 | G9: =J8 -> 2111308.7 | I9: =MIN(D9,G9) -> 20000 | J9: =G9-I9+H9 -> 2091308.7
A10: 32 | B10: 45919 | C10: Friday | D10: =Parâmetros!B5 -> 20000 | E10: 45919 | F10: =D10 -> 20000 | G10: =J9 -> 2091308.7 | I10: =MIN(D10,G10) -> 20000 | J10: =G10-I10+H10 -> 2071308.7
A11: 33 | B11: 45926 | C11: Friday | D11: =Parâmetros!B5 -> 20000 | E11: 45926 | F11: 20000 | G11: =J10 -> 2071308.7 | I11: =MIN(D11,G11) -> 20000 | J11: =G11-I11+H11 -> 2051308.7
A12: 34 | B12: 45929 | C12: Monday | D12: =Parâmetros!B5 -> 20000 | G12: =J11 -> 2051308.7 | H12: 0.0122 | I12: =MIN(D12,G12) -> 20000 | J12: =G12-I12+H12 -> 2031308.7
A13: 35 | B13: 45933 | C13: Friday | D13: =Parâmetros!B5 -> 20000 | G13: =J12 -> 2031308.7 | I13: =MIN(D13,G13) -> 20000 | J13: =SUM(G13-I13)*H13+(G13-I13) -> 2011308.7
A14: 36 | B14: 45936 | C14: Monday | D14: =Parâmetros!B5 -> 20000 | G14: =J13 -> 2011308.7 | I14: =MIN(D14,G14) -> 20000 | J14: =SUM(G14-I14)*H14+(G14-I14) -> 1991308.7
A15: 37 | B15: 45940 | C15: Friday | D15: =Parâmetros!B5 -> 20000 | G15: =J14 -> 1991308.7 | I15: =MIN(D15,G15) -> 20000 | J15: =SUM(G15-I15)*H15+(G15-I15) -> 1971308.7
A16: 38 | B16: 45943 | C16: Monday | D16: =Parâmetros!B5 -> 20000 | G16: =J15 -> 1971308.7 | I16: =MIN(D16,G16) -> 20000 | J16: =SUM(G16-I16)*H16+(G16-I16) -> 1951308.7
A17: 39 | B17: 45947 | C17: Friday | D17: =Parâmetros!B5 -> 20000 | G17: =J16 -> 1951308.7 | I17: =MIN(D17,G17) -> 20000 | J17: =SUM(G17-I17)*H17+(G17-I17) -> 1931308.7
A18: 40 | B18: 45950 | C18: Monday | D18: =Parâmetros!B5 -> 20000 | G18: =J17 -> 1931308.7 | I18: =MIN(D18,G18) -> 20000 | J18: =SUM(G18-I18)*H18+(G18-I18) -> 1911308.7
A19: 41 | B19: 45954 | C19: Friday | D19: =Parâmetros!B5 -> 20000 | G19: =J18 -> 1911308.7 | I19: =MIN(D19,G19) -> 20000 | J19: =SUM(G19-I19)*H19+(G19-I19) -> 1891308.7
A20: 42 | B20: 45957 | C20: Monday | D20: =Parâmetros!B5 -> 20000 | G20: =J19 -> 1891308.7 | I20: =MIN(D20,G20) -> 20000 | J20: =SUM(G20-I20)*H20+(G20-I20) -> 1871308.7
A21: 43 | B21: 45961 | C21: Friday | D21: =Parâmetros!B5 -> 20000 | G21: =J20 -> 1871308.7 | H21: 0.0128 | I21: =MIN(D21,G21) -> 20000 | J21: =SUM(G21-I21)*H21+(G21-I21) -> 1875005.4
A22: 44 | B22: 45964 | C22: Monday | D22: =Parâmetros!B5 -> 20000 | G22: =J21 -> 1875005.4 | I22: =MIN(D22,G22) -> 20000 | J22: =SUM(G22-I22)*H22+(G22-I22) -> 1855005.4
A23: 45 | B23: 45968 | C23: Friday | D23: =Parâmetros!B5 -> 20000 | G23: =J22 -> 1855005.4 | I23: =MIN(D23,G23) -> 20000 | J23: =SUM(G23-I23)*H23+(G23-I23) -> 1835005.4
A24: 46 | B24: 45971 | C24: Monday | D24: =Parâmetros!B5 -> 20000 | G24: =J23 -> 1835005.4 | I24: =MIN(D24,G24) -> 20000 | J24: =SUM(G24-I24)*H24+(G24-I24) -> 1815005.4
A25: 47 | B25: 45975 | C25: Friday | D25: =Parâmetros!B5 -> 20000 | G25: =J24 -> 1815005.4 | I25: =MIN(D25,G25) -> 20000 | J25: =SUM(G25-I25)*H25+(G25-I25) -> 1795005.4
A26: 48 | B26: 45978 | C26: Monday | D26: =Parâmetros!B5 -> 20000 | G26: =J25 -> 1795005.4 | I26: =MIN(D26,G26) -> 20000 | J26: =SUM(G26-I26)*H26+(G26-I26) -> 1775005.4
A27: 49 | B27: 45982 | C27: Friday | D27: =Parâmetros!B5 -> 20000 | G27: =J26 -> 1775005.4 | I27: =MIN(D27,G27) -> 20000 | J27: =SUM(G27-I27)*H27+(G27-I27) -> 1755005.4
A28: 50 | B28: 45985 | C28: Monday | D28: =Parâmetros!B5 -> 20000 | G28: =J27 -> 1755005.4 | I28: =MIN(D28,G28) -> 20000 | J28: =SUM(G28-I28)*H28+(G28-I28) -> 1735005.4
A29: 51 | B29: 45989 | C29: Friday | D29: =Parâmetros!B5 -> 20000 | G29: =J28 -> 1735005.4 | H29: 0.0105 | I29: =MIN(D29,G29) -> 20000 | J29: =SUM(G29-I29)*H29+(G29-I29) -> 1733013
A30: 52 | B30: 45992 | C30: Monday | D30: =Parâmetros!B5 -> 20000 | G30: =J29 -> 1733013 | I30: =MIN(D30,G30) -> 20000 | J30: =SUM(G30-I30)*H30+(G30-I30) -> 1713013
A31: 53 | B31: 45996 | C31: Friday | D31: =Parâmetros!B5 -> 20000 | G31: =J30 -> 1713013 | I31: =MIN(D31,G31) -> 20000 | J31: =SUM(G31-I31)*H31+(G31-I31) -> 1693013
A32: 54 | B32: 45999 | C32: Monday | D32: =Parâmetros!B5 -> 20000 | G32: =J31 -> 1693013 | I32: =MIN(D32,G32) -> 20000 | J32: =SUM(G32-I32)*H32+(G32-I32) -> 1673013
A33: 55 | B33: 46003 | C33: Friday | D33: =Parâmetros!B5 -> 20000 | G33: =J32 -> 1673013 | I33: =MIN(D33,G33) -> 20000 | J33: =SUM(G33-I33)*H33+(G33-I33) -> 1653013
A34: 56 | B34: 46006 | C34: Monday | D34: =Parâmetros!B5 -> 20000 | G34: =J33 -> 1653013 | I34: =MIN(D34,G34) -> 20000 | J34: =SUM(G34-I34)*H34+(G34-I34) -> 1633013
A35: 57 | B35: 46010 | C35: Friday | D35: =Parâmetros!B5 -> 20000 | G35: =J34 -> 1633013 | I35: =MIN(D35,G35) -> 20000 | J35: =SUM(G35-I35)*H35+(G35-I35) -> 1613013
A36: 58 | B36: 46013 | C36: Monday | D36: =Parâmetros!B5 -> 20000 | G36: =J35 -> 1613013 | I36: =MIN(D36,G36) -> 20000 | J36: =SUM(G36-I36)*H36+(G36-I36) -> 1593013
A37: 59 | B37: 46017 | C37: Friday | D37: =Parâmetros!B5 -> 20000 | G37: =J36 -> 1593013 | I37: =MIN(D37,G37) -> 20000 | J37: =SUM(G37-I37)*H37+(G37-I37) -> 1573013
A38: 60 | B38: 46020 | C38: Monday | D38: =Parâmetros!B5 -> 20000 | G38: =J37 -> 1573013 | H38: 0.0122 | I38: =MIN(D38,G38) -> 20000 | J38: =SUM(G38-I38)*H38+(G38-I38) -> 1571959.7
A39: 61 | B39: 46024 | C39: Friday | D39: =Parâmetros!B5 -> 20000 | G39: =J38 -> 1571959.7 | I39: =MIN(D39,G39) -> 20000 | J39: =SUM(G39-I39)*H39+(G39-I39) -> 1551959.7
A40: 62 | B40: 46027 | C40: Monday | D40: =Parâmetros!B5 -> 20000 | G40: =J39 -> 1551959.7 | I40: =MIN(D40,G40) -> 20000 | J40: =SUM(G40-I40)*H40+(G40-I40) -> 1531959.7
A41: 63 | B41: 46031 | C41: Friday | D41: =Parâmetros!B5 -> 20000 | G41: =J40 -> 1531959.7 | I41: =MIN(D41,G41) -> 20000 | J41: =SUM(G41-I41)*H41+(G41-I41) -> 1511959.7
...
